Workbook

Sheet Sheet1
A1: Lead_ID | B1: Lead_Date | C1: Lead_Source | D1: Location | E1: Property_Type | F1: Budget | G1: Call_Attempts | H1: Call_Status | I1: Follow_Up | J1: Site_Visit | K1: Lead_Status | L1: Sales_Value
A2: L001 | B2: 46143 | C2: Website | D2: Chennai | E2: Apartment | F2: 4500000 | G2: 2 | H2: Connected | I2: Yes | J2: Yes | K2: Converted | L2: 4500000
A3: L002 | B3: 46143 | C3: Facebook | D3: Coimbatore | E3: Villa | F3: 7500000 | G3: 1 | H3: Connected | I3: Yes | J3: No | K3: Follow-up
A4: L003 | B4: 46174 | C4: Google | D4: Chennai | E4: Plot | F4: 3000000 | G4: 3 | H4: Connected | I4: No | J4: No | K4: Lost
A5: L004 | B5: 46174 | C5: Instagram | D5: Tambaram | E5: Apartment | F5: 5000000 | G5: 2 | H5: Connected | I5: Yes | J5: Yes | K5: Converted | L5: 5000000
A6: L005 | B6: 46204 | C6: Referral | D6: Chengalpattu | E6: Villa | F6: 8500000 | G6: 1 | H6: Connected | I6: Yes | J6: Yes | K6: Converted | L6: 8500000
A7: L006 | B7: 46204 | C7: Property Portal | D7: Chennai | E7: Apartment | F7: 4000000 | G7: 4 | H7: Not Connected | I7: Yes | J7: No | K7: Follow-up
A8: L007 | B8: 46235 | C8: Facebook | D8: Coimbatore | E8: Plot | F8: 2500000 | G8: 2 | H8: Connected | I8: No | J8: No | K8: Lost
A9: L008 | B9: 46235 | C9: Website | D9: Chennai | E9: Villa | F9: 9000000 | G9: 3 | H9: Connected | I9: Yes | J9: Yes | K9: Converted | L9: 9000000
A10: L009 | B10: 46266 | C10: Google | D10: Tambaram | E10: Apartment | F10: 5500000 | G10: 2 | H10: Connected | I10: Yes | J10: No | K10: Follow-up
A11: L010 | B11: 46266 | C11: Instagram | D11: Chengalpattu | E11: Plot | F11: 2800000 | G11: 1 | H11: Not Connected | I11: No | J11: No | K11: Lost

Sheet Raw_Data
A1: Lead_ID | B1: Lead_Date | C1: Lead_Source | D1: Location | E1: Property_Type | F1: Budget | G1: Call_Attempts | H1: Call_Status | I1: Follow_Up | J1: Site_Visit | K1: Lead_Status | L1: Sales_Value | M1: Budget_Range
A2: L0001 | B2: 46023 | C2: Google | D2: Thudiyalur | E2: Apartment | F2: 5765637 | G2: 5 | H2: Connected | I2: Yes | J2: No | K2: Follow-up | M2: =IF(F2<3000000,"Below 30L",IF(F2<5000000,"30L-50L",IF(F2<8000000,"50L-80L",IF(F2<12000000,"80L-1.2Cr","Above 1.2Cr")))) -> 50L-80L
A3: L0002 | B3: 46023.226 | C3: Referral | D3: periyanayakanpalayam | E3: Apartment | F3: 4024374 | G3: 5 | H3: Connected | I3: Yes | J3: Yes | K3: Follow-up | M3: =IF(F3<3000000,"Below 30L",IF(F3<5000000,"30L-50L",IF(F3<8000000,"50L-80L",IF(F3<12000000,"80L-1.2Cr","Above 1.2Cr")))) -> 30L-50L
A4: L0003 | B4: 46023.452 | C4: Property Portal | D4: Saravanampatti | E4: Plot | F4: 4335056 | G4: 2 | H4: Connected | I4: Yes | J4: Yes | K4: Converted | L4: 4400000 | M4: =IF(F4<3000000,"Below 30L",IF(F4<5000000,"30L-50L",IF(F4<8000000,"50L-80L",IF(F4<12000000,"80L-1.2Cr","Above 1.2Cr")))) -> 30L-50L
A5: L0004 | B5: 46023.679 | C5: Instagram | D5: Ramanathapuram | E5: Apartment | F5: 6773587 | G5: 4 | H5: Not Connected | I5: Yes | J5: No | K5: Follow-up | M5: =IF(F5<3000000,"Below 30L",IF(F5<5000000,"30L-50L",IF(F5<8000000,"50L-80L",IF(F5<12000000,"80L-1.2Cr","Above 1.2Cr")))) -> 50L-80L
A6: L0005 | B6: 46023.905 | C6: Website | D6: panneermadai | E6: Apartment | F6: 3823759 | G6: 4 | H6: Connected | I6: No | J6: No | K6: Lost | M6: =IF(F6<3000000,"Below 30L",IF(F6<5000000,"30L-50L",IF(F6<8000000,"50L-80L",IF(F6<12000000,"80L-1.2Cr","Above 1.2Cr")))) -> 30L-50L
A7: L0006 | B7: 46024.131 | C7: Website | D7: Ramanathapuram | E7: Villa | F7: 7679328 | G7: 6 | H7: Connected | I7: Yes | J7: No | K7: Follow-up | M7: =IF(F7<3000000,"Below 30L",IF(F7<5000000,"30L-50L",IF(F7<8000000,"50L-80L",IF(F7<12000000,"80L-1.2Cr","Above 1.2Cr")))) -> 50L-80L
A8: L0007 | B8: 46024.357 | C8: Website | D8: Ramanathapuram | E8: Apartment | F8: 4650654 | G8: 3 | H8: Not Connected | I8: No | J8: No | K8: Lost | M8: =IF(F8<3000000,"Below 30L",IF(F8<5000000,"30L-50L",IF(F8<8000000,"50L-80L",IF(F8<12000000,"80L-1.2Cr","Above 1.2Cr")))) -> 30L-50L
A9: L0008 | B9: 46024.584 | C9: Property Portal | D9: panneermadai | E9: Villa | F9: 6092036 | G9: 1 | H9: Not Connected | I9: No | J9: No | K9: Lost | M9: =IF(F9<3000000,"Below 30L",IF(F9<5000000,"30L-50L",IF(F9<8000000,"50L-80L",IF(F9<12000000,"80L-1.2Cr","Above 1.2Cr")))) -> 50L-80L
A10: L0009 | B10: 46024.81 | C10: Instagram | D10: Thudiyalur | E10: Apartment | F10: 3853392 | G10: 3 | H10: Connected | I10: No | J10: No | K10: Lost | M10: =IF(F10<3000000,"Below 30L",IF(F10<5000000,"30L-50L",IF(F10<8000000,"50L-80L",IF(F10<12000000,"80L-1.2Cr","Above 1.2Cr")))) -> 30L-50L
A11: L0010 | B11: 46025.036 | C11: Instagram | D11: periyanayakanpalayam | E11: Apartment | F11: 7690457 | G11: 3 | H11: Connected | I11: Yes | J11: No | K11: Follow-up | M11: =IF(F11<3000000,"Below 30L",IF(F11<5000000,"30L-50L",IF(F11<8000000,"50L-80L",IF(F11<12000000,"80L-1.2Cr","Above 1.2Cr")))) -> 50L-80L
A12: L0011 | B12: 46025.262 | C12: Website | D12: Thudiyalur | E12: Apartment | F12: 6654693 | G12: 3 | H12: Not Connected | I12: No | J12: No | K12: Lost | M12: =IF(F12<3000000,"Below 30L",IF(F12<5000000,"30L-50L",IF(F12<8000000,"50L-80L",IF(F12<12000000,"80L-1.2Cr","Above 1.2Cr")))) -> 50L-80L
A13: L0012 | B13: 46025.488 | C13: Referral | D13: Saravanampatti | E13: Apartment | F13: 3293946 | G13: 2 | H13: Connected | I13: Yes | J13: No | K13: Follow-up | M13: =IF(F13<3000000,"Below 30L",IF(F13<5000000,"30L-50L",IF(F13<8000000,"50L-80L",IF(F13<12000000,"80L-1.2Cr","Above 1.2Cr")))) -> 30L-50L
A14: L0013 | B14: 46025.715 | C14: Property Portal | D14: Saravanampatti | E14: Plot | F14: 2142927 | G14: 5 | H14: Connected | I14: Yes | J14: No | K14: Follow-up | M14: =IF(F14<3000000,"Below 30L",IF(F14<5000000,"30L-50L",IF(F14<8000000,"50L-80L",IF(F14<12000000,"80L-1.2Cr","Above 1.2Cr")))) -> Below 30L
A15: L0014 | B15: 46025.941 | C15: Google | D15: Thudiyalur | E15: Apartment | F15: 4266389 | G15: 6 | H15: Connected | I15: Yes | J15: No | K15: Follow-up | M15: =IF(F15<3000000,"Below 30L",IF(F15<5000000,"30L-50L",IF(F15<8000000,"50L-80L",IF(F15<12000000,"80L-1.2Cr","Above 1.2Cr")))) -> 30L-50L
A16: L0015 | B16: 46026.167 | C16: Website | D16: Ramanathapuram | E16: Apartment | F16: 4388509 | G16: 1 | H16: Not Connected | I16: No | J16: No | K16: Lost | M16: =IF(F16<3000000,"Below 30L",IF(F16<5000000,"30L-50L",IF(F16<8000000,"50L-80L",IF(F16<12000000,"80L-1.2Cr","Above 1.2Cr")))) -> 30L-50L
... A18: L0017 | B18: 46026.62 | C18: Google | D18: Thudiyalur | E18: Apartment | F18: 8994134 | G18: 1 | H18: Not Connected | I18: No | J18: No | K18: Lost | M18: =IF(F18<3000000,"Below 30L",IF(F18<5000000,"30L-50L",IF(F18<8000000,"50L-80L",IF(F18<12000000,"80L-1.2Cr","Above 1.2Cr")))) -> 80L-1.2Cr
A19: L0018 | B19: 46026.846 | C19: Facebook | D19: periyanayakanpalayam | E19: Plot | F19: 4123854 | G19: 4 | H19: Connected | I19: Yes | J19: Yes | K19: Converted | L19: 3900000 | M19: =IF(F19<3000000,"Below 30L",IF(F19<5000000,"30L-50L",IF(F19<8000000,"50L-80L",IF(F19<12000000,"80L-1.2Cr","Above 1.2Cr")))) -> 30L-50L
A20: L0019 | B20: 46027.072 | C20: Facebook | D20: Saravanampatti | E20: Apartment | F20: 4983456 | G20: 3 | H20: Not Connected | I20: Yes | J20: No | K20: Follow-up | M20: =IF(F20<3000000,"Below 30L",IF(F20<5000000,"30L-50L",IF(F20<8000000,"50L-80L",IF(F20<12000000,"80L-1.2Cr","Above 1.2Cr")))) -> 30L-50L
A21: L0020 | B21: 46027.298 | C21: Google | D21: Thudiyalur | E21: Villa | F21: 11879960 | G21: 3 | H21: Connected | I21: Yes | J21: Yes | K21: Follow-up | M21: =IF(F21<3000000,"Below 30L",IF(F21<5000000,"30L-50L",IF(F21<8000000,"50L-80L",IF(F21<12000000,"80L-1.2Cr","Above 1.2Cr")))) -> 80L-1.2Cr
A22: L0021 | B22: 46027.525 | C22: Instagram | D22: Ramanathapuram | E22: Plot | F22: 5251672 | G22: 2 | H22: Connected | I22: No | J22: No | K22: Lost | M22: =IF(F22<3000000,"Below 30L",IF(F22<5000000,"30L-50L",IF(F22<8000000,"50L-80L",IF(F22<12000000,"80L-1.2Cr","Above 1.2Cr")))) -> 50L-80L
A23: L0022 | B23: 46027.751 | C23: Website | D23: Coimbatore | E23: Villa | F23: 7624777 | G23: 3 | H23: Connected | I23: Yes | J23: Yes | K23: Converted | L23: 7450000 | M23: =IF(F23<3000000,"Below 30L",IF(F23<5000000,"30L-50L",IF(F23<8000000,"50L-80L",IF(F23<12000000,"80L-1.2Cr","Above 1.2Cr")))) -> 50L-80L
A24: L0023 | B24: 46027.977 | C24: Google | D24: Saravanampatti | E24: Plot | F24: 5514266 | G24: 2 | H24: Connected | I24: Yes | J24: No | K24: Follow-up | M24: =IF(F24<3000000,"Below 30L",IF(F24<5000000,"30L-50L",IF(F24<8000000,"50L-80L",IF(F24<12000000,"80L-1.2Cr","Above 1.2Cr")))) -> 50L-80L
A25: L0024 | B25: 46028.203 | C25: Google | D25: Saravanampatti | E25: Apartment | F25: 4729578 | G25: 2 | H25: Connected | I25: No | J25: Yes | K25: Lost | M25: =IF(F25<3000000,"Below 30L",IF(F25<5000000,"30L-50L",IF(F25<8000000,"50L-80L",IF(F25<12000000,"80L-1.2Cr","Above 1.2Cr")))) -> 30L-50L
A26: L0025 | B26: 46028.429 | C26: Facebook | D26: Saravanampatti | E26: Apartment | F26: 3095556 | G26: 4 | H26: Connected | I26: Yes | J26: No | K26: Follow-up | M26: =IF(F26<3000000,"Below 30L",IF(F26<5000000,"30L-50L",IF(F26<8000000,"50L-80L",IF(F26<12000000,"80L-1.2Cr","Above 1.2Cr")))) -> 30L-50L
A27: L0026 | B27: 46028.656 | C27: Property Portal | D27: periyanayakanpalayam | E27: Apartment | F27: 8992357 | G27: 6 | H27: Connected | I27: No | J27: No | K27: Lost | M27: =IF(F27<3000000,"Below 30L",IF(F27<5000000,"30L-50L",IF(F27<8000000,"50L-80L",IF(F27<12000000,"80L-1.2Cr","Above 1.2Cr")))) -> 80L-1.2Cr
A28: L0027 | B28: 46028.882 | C28: Website | D28: Saravanampatti | E28: Villa | F28: 6652755 | G28: 5 | H28: Connected | I28: Yes | J28: No | K28: Converted | L28: 6550000 | M28: =IF(F28<3000000,"Below 30L",IF(F28<5000000,"30L-50L",IF(F28<8000000,"50L-80L",IF(F28<12000000,"80L-1.2Cr","Above 1.2Cr")))) -> 50L-80L
A29: L0028 | B29: 46029.108 | C29: Facebook | D29: panneermadai | E29: Plot | F29: 2929210 | G29: 5 | H29: Connected | I29: Yes | J29: Yes | K29: Converted | L29: 2800000 | M29: =IF(F29<3000000,"Below 30L",IF(F29<5000000,"30L-50L",IF(F29<8000000,"50L-80L",IF(F29<12000000,"80L-1.2Cr","Above 1.2Cr")))) -> Below 30L
A30: L0029 | B30: 46029.334 | C30: Instagram | D30: Coimbatore | E30: Apartment | F30: 5838951 | G30: 2 | H30: Not Connected | I30: No | J30: No | K30: Lost | M30: =IF(F30<3000000,"Below 30L",IF(F30<5000000,"30L-50L",IF(F30<8000000,"50L-80L",IF(F30<12000000,"80L-1.2Cr","Above 1.2Cr")))) -> 50L-80L
A31: L0030 | B31: 46029.561 | C31: Website | D31: panneermadai | E31: Villa | F31: 7094409 | G31: 2 | H31: Not Connected | I31: No | J31: No | K31: Lost | M31: =IF(F31<3000000,"Below 30L",IF(F31<5000000,"30L-50L",IF(F31<8000000,"50L-80L",IF(F31<12000000,"80L-1.2Cr","Above 1.2Cr")))) -> 50L-80L
A32: L0031 | B32: 46029.787 | C32: Instagram | D32: Thudiyalur | E32: Apartment | F32: 6283587 | G32: 4 | H32: Connected | I32: No | J32: Yes | K32: Converted | L32: 6200000 | M32: =IF(F32<3000000,"Below 30L",IF(F32<5000000,"30L-50L",IF(F32<8000000,"50L-80L",IF(F32<12000000,"80L-1.2Cr","Above 1.2Cr")))) -> 50L-80L
A33: L0032 | B33: 46030.013 | C33: Website | D33: periyanayakanpalayam | E33: Villa | F33: 7513083 | G33: 5 | H33: Connected | I33: Yes | J33: Yes | K33: Follow-up | M33: =IF(F33<3000000,"Below 30L",IF(F33<5000000,"30L-50L",IF(F33<8000000,"50L-80L",IF(F33<12000000,"80L-1.2Cr","Above 1.2Cr")))) -> 50L-80L
A34: L0033 | B34: 46030.239 | C34: Website | D34: Thudiyalur | E34: Apartment | F34: 5898950 | G34: 1 | H34: Not Connected | I34: Yes | J34: No | K34: Follow-up | M34: =IF(F34<3000000,"Below 30L",IF(F34<5000000,"30L-50L",IF(F34<8000000,"50L-80L",IF(F34<12000000,"80L-1.2Cr","Above 1.2Cr")))) -> 50L-80L
A35: L0034 | B35: 46030.465 | C35: Referral | D35: Thudiyalur | E35: Plot | F35: 5522155 | G35: 2 | H35: Connected | I35: No | J35: No | K35: Lost | M35: =IF(F35<3000000,"Below 30L",IF(F35<5000000,"30L-50L",IF(F35<8000000,"50L-80L",IF(F35<12000000,"80L-1.2Cr","Above 1.2Cr")))) -> 50L-80L
A36: L0035 | B36: 46030.692 | C36: Referral | D36: Thudiyalur | E36: Villa | F36: 9511931 | G36: 1 | H36: Connected | I36: Yes | J36: No | K36: Follow-up | M36: =IF(F36<3000000,"Below 30L",IF(F36<5000000,"30L-50L",IF(F36<8000000,"50L-80L",IF(F36<12000000,"80L-1.2Cr","Above 1.2Cr")))) -> 80L-1.2Cr
A37: L0036 | B37: 46030.918 | C37: Property Portal | D37: Ramanathapuram | E37: Apartment | F37: 4079525 | G37: 3 | H37: Connected | I37: No | J37: Yes | K37: Converted | L37: 3900000 | M37: =IF(F37<3000000,"Below 30L",IF(F37<5000000,"30L-50L",IF(F37<8000000,"50L-80L",IF(F37<12000000,"80L-1.2Cr","Above 1.2Cr")))) -> 30L-50L
A38: L0037 | B38: 46031.144 | C38: Google | D38: Coimbatore | E38: Apartment | F38: 3854568 | G38: 2 | H38: Connected | I38: Yes | J38: Yes | K38: Converted | L38: 3900000 | M38: =IF(F38<3000000,"Below 30L",IF(F38<5000000,"30L-50L",IF(F38<8000000,"50L-80L",IF(F38<12000000,"80L-1.2Cr","Above 1.2Cr")))) -> 30L-50L
A39: L0038 | B39: 46031.37 | C39: Website | D39: Ramanathapuram | E39: Apartment | F39: 3061842 | G39: 2 | H39: Not Connected | I39: No | J39: No | K39: Lost | M39: =IF(F39<3000000,"Below 30L",IF(F39<5000000,"30L-50L",IF(F39<8000000,"50L-80L",IF(F39<12000000,"80L-1.2Cr","Above 1.2Cr")))) -> 30L-50L
A40: L0039 | B40: 46031.597 | C40: Instagram | D40: Thudiyalur | E40: Apartment | F40: 4789135 | G40: 1 | H40: Connected | I40: Yes | J40: No | K40: Follow-up | M40: =IF(F40<3000000,"Below 30L",IF(F40<5000000,"30L-50L",IF(F40<8000000,"50L-80L",IF(F40<12000000,"80L-1.2Cr","Above 1.2Cr")))) -> 30L-50L
A41: L0040 | B41: 46031.823 | C41: Facebook | D41: Coimbatore | E41: Apartment | F41: 4630357 | G41: 2 | H41: Not Connected | I41: Yes | J41: No | K41: Follow-up | M41: =IF(F41<3000000,"Below 30L",IF(F41<5000000,"30L-50L",IF(F41<8000000,"50L-80L",IF(F41<12000000,"80L-1.2Cr","Above 1.2Cr")))) -> 30L-50L
...

Sheet lead_source Analysis
A2: Count of Lead_ID | B2: Column Labels
A3: Row Labels | B3: Converted | C3: Follow-up | D3: Lost | E3: Grand Total
A4: Facebook | B4: 28 | C4: 75 | D4: 62 | E4: 165
A5: Google | B5: 44 | C5: 74 | D5: 78 | E5: 196
A6: Instagram | B6: 22 | C6: 72 | D6: 58 | E6: 152
A7: Property Portal | B7: 28 | C7: 71 | D7: 62 | E7: 161
A8: Referral | B8: 27 | C8: 40 | D8: 33 | E8: 100
A9: Unknown | C9: 1 | E9: 1
A10: Website | B10: 53 | C10: 81 | D10: 91 | E10: 225
A11: Grand Total | B11: 202 | C11: 414 | D11: 384 | E11: 1000

Sheet Property_Type_Analysis
A2: Count of Lead_ID | B2: Column Labels
A3: Row Labels | B3: Converted | C3: Follow-up | D3: Lost | E3: Grand Total
A4: Apartment | B4: 107 | C4: 233 | D4: 214 | E4: 554
A5: Plot | B5: 41 | C5: 76 | D5: 87 | E5: 204
A6: Unknown | C6: 1 | E6: 1
A7: Villa | B7: 54 | C7: 104 | D7: 83 | E7: 241
A8: Grand Total | B8: 202 | C8: 414 | D8: 384 | E8: 1000

Sheet Location_Analysis
A2: Count of Lead_ID | B2: Column Labels
A3: Row Labels | B3: Converted | C3: Follow-up | D3: Lost | E3: Grand Total
A4: Coimbatore | B4: 22 | C4: 58 | D4: 61 | E4: 141
A5: Unknown | C5: 1 | E5: 1
A6: Thudiyalur | B6: 48 | C6: 126 | D6: 109 | E6: 283
A7: periyanayakanpalayam | B7: 31 | C7: 52 | D7: 63 | E7: 146
A8: Saravanampatti | B8: 37 | C8: 56 | D8: 54 | E8: 147
A9: Ramanathapuram | B9: 40 | C9: 69 | D9: 58 | E9: 167
A10: panneermadai | B10: 24 | C10: 52 | D10: 39 | E10: 115
A11: Grand Total | B11: 202 | C11: 414 | D11: 384 | E11: 1000

Sheet Budget Analysis
A2: Count of Lead_ID | B2: Column Labels
A3: Row Labels | B3: Converted | C3: Follow-up | D3: Lost | E3: Grand Total
A4: 30L-50L | B4: 75 | C4: 155 | D4: 155 | E4: 385
A5: 50L-80L | B5: 65 | C5: 131 | D5: 126 | E5: 322
A6: 80L-1.2Cr | B6: 35 | C6: 80 | D6: 48 | E6: 163
A7: Above 1.2Cr | B7: 7 | C7: 8 | D7: 15 | E7: 30
A8: Below 30L | B8: 20 | C8: 40 | D8: 40 | E8: 100
A9: Grand Total | B9: 202 | C9: 414 | D9: 384 | E9: 1000

Sheet Call_Attempt_Analysis
A2: Count of Lead_ID | B2: Column Labels
A3: call_Attempts | B3: Converted | C3: Follow-up | D3: Lost | E3: Grand Total
A4: 1 | B4: 41 | C4: 96 | D4: 104 | E4: 241
A5: 2 | B5: 51 | C5: 91 | D5: 116 | E5: 258
A6: 3 | B6: 38 | C6: 87 | D6: 69 | E6: 194
A7: 4 | B7: 43 | C7: 65 | D7: 56 | E7: 164
A8: 5 | B8: 15 | C8: 61 | D8: 26 | E8: 102
A9: 6 | B9: 14 | C9: 14 | D9: 13 | E9: 41
A10: Grand Total | B10: 202 | C10: 414 | D10: 384 | E10: 1000

Sheet Site_Visit_Analysis
A2: Count of Lead_ID | B2: Column Labels
A3: Row Labels | B3: Converted | C3: Follow-up | D3: Lost | E3: Grand Total
A4: No | B4: 47 | C4: 295 | D4: 353 | E4: 695
A5: Yes | B5: 155 | C5: 119 | D5: 31 | E5: 305
A6: Grand Total | B6: 202 | C6: 414 | D6: 384 | E6: 1000

Sheet Analysis
A1: KPI | B1: VALUE
A2: TOTAL LEADS | B2: =COUNTA(Raw_Data!A2:A1001) -> 1000
A3: CONVERTED LEADS | B3: =COUNTIF(Raw_Data!K2:K1001,"Converted") -> 202
A4: Conversation Rate | B4: =B3/B2 -> 0.202
A5: Total Site Visits | B5: =COUNTIF(Raw_Data!J2:J1001,"Yes") -> 305
A6: Connected Leads | B6: =COUNTIF(Raw_Data!H2:H1001,"Connected") -> 721
A7: Total Sales | B7: =SUM(Raw_Data!L2:L1001) -> 1174050000 | D7: =B7/10000000 -> 117.405
A8: Total Follow-ups | B8: =COUNTIF(Raw_Data!I2:I1001,"Yes") -> 559
A9: Lost Leads | B9: =COUNTIF(Raw_Data!K2:K1001,"Lost") -> 384
A10: Site Visit Rate | B10: =B5/B2 -> 0.305
A11: Site Visit to Conversion Rate | B11: =B3/B5 -> 0.66229508

Sheet Source_SiteVisit_Analysis
A2: Count of Lead_ID | B2: Column Labels
A3: Row Labels | B3: No | C3: Yes | D3: Grand Total
A4: Facebook | B4: 114 | C4: 51 | D4: 165
A5: Google | B5: 135 | C5: 61 | D5: 196
A6: Instagram | B6: 110 | C6: 42 | D6: 152
A7: Property Portal | B7: 119 | C7: 42 | D7: 161
A8: Referral | B8: 64 | C8: 36 | D8: 100
A9: Unknown | C9: 1 | D9: 1
A10: Website | B10: 153 | C10: 72 | D10: 225
A11: Grand Total | B11: 695 | C11: 305 | D11: 1000

Sheet Dashboard
